<html><body><div><div class="post-text" itemprop="text">

<p>It appears that one cannot resume the execution of test once you hit the raise the user defined exception in Python. But in my scenario I want to check error occurred for different input values. But Current implementation is restricting to continue the check error for the different input vectors.</p>

<p>However, before coming up with some sort of convoluted solution to my problem, I figured I would ask the experts and see if there is something I'm missing. <strong>Unfortunately, I cannot change this paradigm easily without significant re-factoring</strong>.</p>

<p>My application looks similar to this:</p>

<ul>
<li>Input will be given as numGen function. This numGen function add the input to the random number. In my example I am checking for 10 different random number.</li>
<li>Note Input is also will be varying as well as the range of random number generation</li>
</ul>

<p><strong>Problem statement:</strong></p>

<ul>
<li><p>I want to check for each input whether error is occurred and if any error occurred raise exception and store the information of which input</p></li>
<li><p>Continue the program execution for other input as well, But In my implementation it I'm not able to continue further execution.</p></li>
</ul>

<p>Questions:</p>

<ul>
<li>How to raise the exceptions later, without using unittest module? </li>
</ul>

<p>from random import randint</p>

<pre><code>class RND_ERROR(Exception):
    def __init__(self, ErrNum, *arg, **kwargs):
        self.RND_ERR_NR = int(ErrNum)
        self.RND_ERR_MSG = ""         
        if self.RND_ERR_NR == 0x00000000:
            self.RND_ERR_MSG = "NO ERROR"
        elif self.RND_ERR_NR == 0x00000001:
            self.RND_ERR_MSG = "RANDOM NUMBER IS ONE"
        elif self.RND_ERR_NR == 0x00000002:
            self.RND_ERR_MSG = "RANDOM NUMBER IS TWO"
        elif self.RND_ERR_NR == 0x00000003:
            self.RND_ERR_MSG = "RANDOM NUMBER IS THREE"
        else:
            self.RND_ERR_MSG = "RANDOM NUMBER GREATER THAN THREE"
    def __str__(self):
        return "RND ERROR (0x%08X): %s" % (self.RND_ERR_NR,self.RND_ERR_MSG)

    def __repr__(self):
       return self.__str__()

def check_error(b):
    print "dict",b
    count = 0

    for i, error_nr in b.items():

        error_nr = error_nr % 2
        print "key:val",i, error_nr
        if error_nr ==0:
            count = count +1
            # print count
        elif error_nr &gt; 0:

            # print error_nr
            raise RND_ERROR(error_nr)

def numGen(input):
    from random import randint
    result= {}
    for i in range(9):
        j = (randint(0,4))
        result[i] = input+j
        result.update()
    check_error(result)

if __name__ == '__main__':
    try:
        numGen(3)
    except BaseException as e:
        print e

Output1: # Since at the 6th input error occurred and execution stopped **(Some what Best case)**  
dict {0: 6, 1: 6, 2: 6, 3: 6, 4: 4, 5: 6, 6: 3, 7: 3, 8: 7}
key:val 0 0
key:val 1 0
key:val 2 0
key:val 3 0
key:val 4 0
key:val 5 0
key:val 6 1
RND ERROR (0x00000001): RANDOM NUMBER IS ONE

**Output2:**
dict {0: 7, 1: 6, 2: 4, 3: 3, 4: 6, 5: 6, 6: 7, 7: 5, 8: 4}
key:val 0 1

RND ERROR (0x00000001): RANDOM NUMBER IS ONE

Expected Output:

Input1 - Pass
Input2 - Pass
Input3 - Pass
Input4 - Pass
Input5 - Pass
Input6 - RANDOM IS TWO (exception occurred)
Input7 - Pass  # execution continued for next input check
Input8 - Pass
Input9 - RANDOM IS ONE (exception occurred)
Input10 - Pass  # execution continued for next input check
</code></pre>

<p>I found link, which looks similar to my requirement. Difference is instead of checking error in file reading and stack up the error if found. In my case it is checking for inputs.</p>

<p><a href="http://stackoverflow.com/questions/18655481/a-pythonic-way-for-resume-next-on-exceptions">Similar requirement</a></p>

<p>Thanks in advance!!</p>
    </div>
    </div></body></html>